{"uuid": "69f8b827-cabf-4e71-ad88-2831c041fb9b", "children": ["551054c9-b3ba-4a1a-b388-7b523a1f6146"], "befores": [{"name": "driver", "status": "broken", "statusDetails": {"message": "selenium.common.exceptions.WebDriverException: Message: unknown error: Chrome failed to start: exited normally.\n  (chrome not reachable)\n  (The process started from chrome location C:\\Program Files\\Google\\Chrome\\Application\\chrome.exe is no longer running, so ChromeDriver is assuming that Chrome has crashed.)\n\n", "trace": "  File \"C:\\Users\\79605\\AppData\\Local\\Programs\\Python\\Python37\\lib\\site-packages\\pluggy\\callers.py\", line 187, in _multicall\n    res = hook_impl.function(*args)\n  File \"C:\\Users\\79605\\AppData\\Local\\Programs\\Python\\Python37\\lib\\site-packages\\_pytest\\fixtures.py\", line 918, in pytest_fixture_setup\n    result = call_fixture_func(fixturefunc, request, kwargs)\n  File \"C:\\Users\\79605\\AppData\\Local\\Programs\\Python\\Python37\\lib\\site-packages\\_pytest\\fixtures.py\", line 774, in call_fixture_func\n    res = next(it)\n  File \"C:\\Development\\autotests\\conftest.py\", line 15, in driver\n    _driver = webdriver.Chrome()\n  File \"C:\\Users\\79605\\AppData\\Local\\Programs\\Python\\Python37\\lib\\site-packages\\selenium\\webdriver\\chrome\\webdriver.py\", line 75, in __init__\n    desired_capabilities=desired_capabilities)\n  File \"C:\\Users\\79605\\AppData\\Local\\Programs\\Python\\Python37\\lib\\site-packages\\selenium\\webdriver\\remote\\webdriver.py\", line 156, in __init__\n    self.start_session(capabilities, browser_profile)\n  File \"C:\\Users\\79605\\AppData\\Local\\Programs\\Python\\Python37\\lib\\site-packages\\selenium\\webdriver\\remote\\webdriver.py\", line 251, in start_session\n    response = self.execute(Command.NEW_SESSION, parameters)\n  File \"C:\\Users\\79605\\AppData\\Local\\Programs\\Python\\Python37\\lib\\site-packages\\selenium\\webdriver\\remote\\webdriver.py\", line 320, in execute\n    self.error_handler.check_response(response)\n  File \"C:\\Users\\79605\\AppData\\Local\\Programs\\Python\\Python37\\lib\\site-packages\\selenium\\webdriver\\remote\\errorhandler.py\", line 242, in check_response\n    raise exception_class(message, screen, stacktrace)\n"}, "start": 1608992181876, "stop": 1608992188530}], "start": 1608992181876, "stop": 1608992188571}